Failure in python_multiple_errors.py:

  The CHECK on line 7 wants:
    eins

  which failed to match line stdout:2:
    one

  Context:
    foo
    one <= does not match CHECK on line 7: eins
    two <= does not match CHECK on line 9: zwei
    bar

  when running command:
    /usr/bin/python3 python_multiple_errors.py
